2024-04-19 10:15:30 - ERROR - Exception occurred in function 'handle_request': KeyError: 'user_id'
Traceback (most recent call last):
  File "app.py", line 56, in handle_request
    user_id = request.json['user_id']
KeyError: 'user_id'

